Workbook

Sheet Sheet5
A1: ='수기_결측치를평균값처리'!A1='파워쿼리_결측치를평균값처리'!A1 -> TRUE | B1: ='수기_결측치를평균값처리'!B1='파워쿼리_결측치를평균값처리'!B1 -> TRUE | C1: ='수기_결측치를평균값처리'!C1='파워쿼리_결측치를평균값처리'!C1 -> TRUE | D1: ='수기_결측치를평균값처리'!D1='파워쿼리_결측치를평균값처리'!D1 -> TRUE | E1: ='수기_결측치를평균값처리'!E1='파워쿼리_결측치를평균값처리'!E1 -> TRUE | F1: ='수기_결측치를평균값처리'!F1='파워쿼리_결측치를평균값처리'!F1 -> TRUE | G1: ='수기_결측치를평균값처리'!G1='파워쿼리_결측치를평균값처리'!G1 -> TRUE | H1: ='수기_결측치를평균값처리'!H1='파워쿼리_결측치를평균값처리'!H1 -> TRUE | ... AF1: ='수기_결측치를평균값처리'!AF1='파워쿼리_결측치를평균값처리'!AF1 -> TRUE
A2: ='수기_결측치를평균값처리'!A2='파워쿼리_결측치를평균값처리'!A2 -> TRUE | B2: ='수기_결측치를평균값처리'!B2-'파워쿼리_결측치를평균값처리'!B2 -> 0 | C2: ='수기_결측치를평균값처리'!C2-'파워쿼리_결측치를평균값처리'!C2 -> 0 | D2: ='수기_결측치를평균값처리'!D2-'파워쿼리_결측치를평균값처리'!D2 -> 0 | E2: ='수기_결측치를평균값처리'!E2-'파워쿼리_결측치를평균값처리'!E2 -> 0 | F2: ='수기_결측치를평균값처리'!F2-'파워쿼리_결측치를평균값처리'!F2 -> 0 | G2: ='수기_결측치를평균값처리'!G2-'파워쿼리_결측치를평균값처리'!G2 -> 0 | H2: ='수기_결측치를평균값처리'!H2-'파워쿼리_결측치를평균값처리'!H2 -> 0 | I2: ='수기_결측치를평균값처리'!I2-'파워쿼리_결측치를평균값처리'!I2 -> 0 | ... AF2: ='수기_결측치를평균값처리'!AF2-'파워쿼리_결측치를평균값처리'!AF2 -> 0
A3: ='수기_결측치를평균값처리'!A3='파워쿼리_결측치를평균값처리'!A3 -> TRUE | B3: ='수기_결측치를평균값처리'!B3-'파워쿼리_결측치를평균값처리'!B3 -> 0 | C3: ='수기_결측치를평균값처리'!C3-'파워쿼리_결측치를평균값처리'!C3 -> 0 | D3: ='수기_결측치를평균값처리'!D3-'파워쿼리_결측치를평균값처리'!D3 -> 0 | E3: ='수기_결측치를평균값처리'!E3-'파워쿼리_결측치를평균값처리'!E3 -> 0 | F3: ='수기_결측치를평균값처리'!F3-'파워쿼리_결측치를평균값처리'!F3 -> 0 | G3: ='수기_결측치를평균값처리'!G3-'파워쿼리_결측치를평균값처리'!G3 -> 0 | H3: ='수기_결측치를평균값처리'!H3-'파워쿼리_결측치를평균값처리'!H3 -> 0 | I3: ='수기_결측치를평균값처리'!I3-'파워쿼리_결측치를평균값처리'!I3 -> 0 | ... AF3: ='수기_결측치를평균값처리'!AF3-'파워쿼리_결측치를평균값처리'!AF3 -> 0
A4: ='수기_결측치를평균값처리'!A4='파워쿼리_결측치를평균값처리'!A4 -> TRUE | B4: ='수기_결측치를평균값처리'!B4-'파워쿼리_결측치를평균값처리'!B4 -> 0 | C4: ='수기_결측치를평균값처리'!C4-'파워쿼리_결측치를평균값처리'!C4 -> 0 | D4: ='수기_결측치를평균값처리'!D4-'파워쿼리_결측치를평균값처리'!D4 -> 0 | E4: ='수기_결측치를평균값처리'!E4-'파워쿼리_결측치를평균값처리'!E4 -> 0 | F4: ='수기_결측치를평균값처리'!F4-'파워쿼리_결측치를평균값처리'!F4 -> 0 | G4: ='수기_결측치를평균값처리'!G4-'파워쿼리_결측치를평균값처리'!G4 -> 0 | H4: ='수기_결측치를평균값처리'!H4-'파워쿼리_결측치를평균값처리'!H4 -> 0 | I4: ='수기_결측치를평균값처리'!I4-'파워쿼리_결측치를평균값처리'!I4 -> 0 | ... AF4: ='수기_결측치를평균값처리'!AF4-'파워쿼리_결측치를평균값처리'!AF4 -> 0
A5: ='수기_결측치를평균값처리'!A5='파워쿼리_결측치를평균값처리'!A5 -> TRUE | B5: ='수기_결측치를평균값처리'!B5-'파워쿼리_결측치를평균값처리'!B5 -> 0 | C5: ='수기_결측치를평균값처리'!C5-'파워쿼리_결측치를평균값처리'!C5 -> 0 | D5: ='수기_결측치를평균값처리'!D5-'파워쿼리_결측치를평균값처리'!D5 -> 0 | E5: ='수기_결측치를평균값처리'!E5-'파워쿼리_결측치를평균값처리'!E5 -> 0 | F5: ='수기_결측치를평균값처리'!F5-'파워쿼리_결측치를평균값처리'!F5 -> 0 | G5: ='수기_결측치를평균값처리'!G5-'파워쿼리_결측치를평균값처리'!G5 -> 0 | H5: ='수기_결측치를평균값처리'!H5-'파워쿼리_결측치를평균값처리'!H5 -> 0 | I5: ='수기_결측치를평균값처리'!I5-'파워쿼리_결측치를평균값처리'!I5 -> 0 | ... AF5: ='수기_결측치를평균값처리'!AF5-'파워쿼리_결측치를평균값처리'!AF5 -> 0
A6: ='수기_결측치를평균값처리'!A6='파워쿼리_결측치를평균값처리'!A6 -> TRUE | B6: ='수기_결측치를평균값처리'!B6-'파워쿼리_결측치를평균값처리'!B6 -> 0 | C6: ='수기_결측치를평균값처리'!C6-'파워쿼리_결측치를평균값처리'!C6 -> 0 | D6: ='수기_결측치를평균값처리'!D6-'파워쿼리_결측치를평균값처리'!D6 -> 0 | E6: ='수기_결측치를평균값처리'!E6-'파워쿼리_결측치를평균값처리'!E6 -> 0 | F6: ='수기_결측치를평균값처리'!F6-'파워쿼리_결측치를평균값처리'!F6 -> 0 | G6: ='수기_결측치를평균값처리'!G6-'파워쿼리_결측치를평균값처리'!G6 -> 0 | H6: ='수기_결측치를평균값처리'!H6-'파워쿼리_결측치를평균값처리'!H6 -> 0 | I6: ='수기_결측치를평균값처리'!I6-'파워쿼리_결측치를평균값처리'!I6 -> 0 | ... AF6: ='수기_결측치를평균값처리'!AF6-'파워쿼리_결측치를평균값처리'!AF6 -> 0
A7: ='수기_결측치를평균값처리'!A7='파워쿼리_결측치를평균값처리'!A7 -> TRUE | B7: ='수기_결측치를평균값처리'!B7-'파워쿼리_결측치를평균값처리'!B7 -> 0 | C7: ='수기_결측치를평균값처리'!C7-'파워쿼리_결측치를평균값처리'!C7 -> 0 | D7: ='수기_결측치를평균값처리'!D7-'파워쿼리_결측치를평균값처리'!D7 -> 0 | E7: ='수기_결측치를평균값처리'!E7-'파워쿼리_결측치를평균값처리'!E7 -> 0 | F7: ='수기_결측치를평균값처리'!F7-'파워쿼리_결측치를평균값처리'!F7 -> 0 | G7: ='수기_결측치를평균값처리'!G7-'파워쿼리_결측치를평균값처리'!G7 -> 0 | H7: ='수기_결측치를평균값처리'!H7-'파워쿼리_결측치를평균값처리'!H7 -> 0 | I7: ='수기_결측치를평균값처리'!I7-'파워쿼리_결측치를평균값처리'!I7 -> 0 | ... AF7: ='수기_결측치를평균값처리'!AF7-'파워쿼리_결측치를평균값처리'!AF7 -> 0
A8: ='수기_결측치를평균값처리'!A8='파워쿼리_결측치를평균값처리'!A8 -> TRUE | B8: ='수기_결측치를평균값처리'!B8-'파워쿼리_결측치를평균값처리'!B8 -> 0 | C8: ='수기_결측치를평균값처리'!C8-'파워쿼리_결측치를평균값처리'!C8 -> 0 | D8: ='수기_결측치를평균값처리'!D8-'파워쿼리_결측치를평균값처리'!D8 -> 0 | E8: ='수기_결측치를평균값처리'!E8-'파워쿼리_결측치를평균값처리'!E8 -> 0 | F8: ='수기_결측치를평균값처리'!F8-'파워쿼리_결측치를평균값처리'!F8 -> 0 | G8: ='수기_결측치를평균값처리'!G8-'파워쿼리_결측치를평균값처리'!G8 -> 0 | H8: ='수기_결측치를평균값처리'!H8-'파워쿼리_결측치를평균값처리'!H8 -> 0 | I8: ='수기_결측치를평균값처리'!I8-'파워쿼리_결측치를평균값처리'!I8 -> 0 | ... AF8: ='수기_결측치를평균값처리'!AF8-'파워쿼리_결측치를평균값처리'!AF8 -> 0
A9: ='수기_결측치를평균값처리'!A9='파워쿼리_결측치를평균값처리'!A9 -> TRUE | B9: ='수기_결측치를평균값처리'!B9-'파워쿼리_결측치를평균값처리'!B9 -> 0 | C9: ='수기_결측치를평균값처리'!C9-'파워쿼리_결측치를평균값처리'!C9 -> 0 | D9: ='수기_결측치를평균값처리'!D9-'파워쿼리_결측치를평균값처리'!D9 -> 0 | E9: ='수기_결측치를평균값처리'!E9-'파워쿼리_결측치를평균값처리'!E9 -> 0 | F9: ='수기_결측치를평균값처리'!F9-'파워쿼리_결측치를평균값처리'!F9 -> 0 | G9: ='수기_결측치를평균값처리'!G9-'파워쿼리_결측치를평균값처리'!G9 -> 0 | H9: ='수기_결측치를평균값처리'!H9-'파워쿼리_결측치를평균값처리'!H9 -> 0 | I9: ='수기_결측치를평균값처리'!I9-'파워쿼리_결측치를평균값처리'!I9 -> 0 | ... AF9: ='수기_결측치를평균값처리'!AF9-'파워쿼리_결측치를평균값처리'!AF9 -> 0
A10: ='수기_결측치를평균값처리'!A10='파워쿼리_결측치를평균값처리'!A10 -> TRUE | B10: ='수기_결측치를평균값처리'!B10-'파워쿼리_결측치를평균값처리'!B10 -> 0 | C10: ='수기_결측치를평균값처리'!C10-'파워쿼리_결측치를평균값처리'!C10 -> 0 | D10: ='수기_결측치를평균값처리'!D10-'파워쿼리_결측치를평균값처리'!D10 -> 0 | E10: ='수기_결측치를평균값처리'!E10-'파워쿼리_결측치를평균값처리'!E10 -> 0 | F10: ='수기_결측치를평균값처리'!F10-'파워쿼리_결측치를평균값처리'!F10 -> 0 | G10: ='수기_결측치를평균값처리'!G10-'파워쿼리_결측치를평균값처리'!G10 -> 0 | H10: ='수기_결측치를평균값처리'!H10-'파워쿼리_결측치를평균값처리'!H10 -> 0 | I10: ='수기_결측치를평균값처리'!I10-'파워쿼리_결측치를평균값처리'!I10 -> 0 | ... AF10: ='수기_결측치를평균값처리'!AF10-'파워쿼리_결측치를평균값처리'!AF10 -> 0
A11: ='수기_결측치를평균값처리'!A11='파워쿼리_결측치를평균값처리'!A11 -> TRUE | B11: ='수기_결측치를평균값처리'!B11-'파워쿼리_결측치를평균값처리'!B11 -> 0 | C11: ='수기_결측치를평균값처리'!C11-'파워쿼리_결측치를평균값처리'!C11 -> 0 | D11: ='수기_결측치를평균값처리'!D11-'파워쿼리_결측치를평균값처리'!D11 -> 0 | E11: ='수기_결측치를평균값처리'!E11-'파워쿼리_결측치를평균값처리'!E11 -> 0 | F11: ='수기_결측치를평균값처리'!F11-'파워쿼리_결측치를평균값처리'!F11 -> 0 | G11: ='수기_결측치를평균값처리'!G11-'파워쿼리_결측치를평균값처리'!G11 -> 0 | H11: ='수기_결측치를평균값처리'!H11-'파워쿼리_결측치를평균값처리'!H11 -> 0 | I11: ='수기_결측치를평균값처리'!I11-'파워쿼리_결측치를평균값처리'!I11 -> 0 | ... AF11: ='수기_결측치를평균값처리'!AF11-'파워쿼리_결측치를평균값처리'!AF11 -> 0
A12: ='수기_결측치를평균값처리'!A12='파워쿼리_결측치를평균값처리'!A12 -> TRUE | B12: ='수기_결측치를평균값처리'!B12-'파워쿼리_결측치를평균값처리'!B12 -> 0 | C12: ='수기_결측치를평균값처리'!C12-'파워쿼리_결측치를평균값처리'!C12 -> 0 | D12: ='수기_결측치를평균값처리'!D12-'파워쿼리_결측치를평균값처리'!D12 -> 0 | E12: ='수기_결측치를평균값처리'!E12-'파워쿼리_결측치를평균값처리'!E12 -> 0 | F12: ='수기_결측치를평균값처리'!F12-'파워쿼리_결측치를평균값처리'!F12 -> 0 | G12: ='수기_결측치를평균값처리'!G12-'파워쿼리_결측치를평균값처리'!G12 -> 0 | H12: ='수기_결측치를평균값처리'!H12-'파워쿼리_결측치를평균값처리'!H12 -> 0 | I12: ='수기_결측치를평균값처리'!I12-'파워쿼리_결측치를평균값처리'!I12 -> 0 | ... AF12: ='수기_결측치를평균값처리'!AF12-'파워쿼리_결측치를평균값처리'!AF12 -> 0
A13: ='수기_결측치를평균값처리'!A13='파워쿼리_결측치를평균값처리'!A13 -> TRUE | B13: ='수기_결측치를평균값처리'!B13-'파워쿼리_결측치를평균값처리'!B13 -> 0 | C13: ='수기_결측치를평균값처리'!C13-'파워쿼리_결측치를평균값처리'!C13 -> 0 | D13: ='수기_결측치를평균값처리'!D13-'파워쿼리_결측치를평균값처리'!D13 -> 0 | E13: ='수기_결측치를평균값처리'!E13-'파워쿼리_결측치를평균값처리'!E13 -> 0 | F13: ='수기_결측치를평균값처리'!F13-'파워쿼리_결측치를평균값처리'!F13 -> 0 | G13: ='수기_결측치를평균값처리'!G13-'파워쿼리_결측치를평균값처리'!G13 -> 0 | H13: ='수기_결측치를평균값처리'!H13-'파워쿼리_결측치를평균값처리'!H13 -> 0 | I13: ='수기_결측치를평균값처리'!I13-'파워쿼리_결측치를평균값처리'!I13 -> 0 | ... AF13: ='수기_결측치를평균값처리'!AF13-'파워쿼리_결측치를평균값처리'!AF13 -> 0
... A570: ='수기_결측치를평균값처리'!A570='파워쿼리_결측치를평균값처리'!A570 -> TRUE | B570: ='수기_결측치를평균값처리'!B570-'파워쿼리_결측치를평균값처리'!B570 -> 0 | C570: ='수기_결측치를평균값처리'!C570-'파워쿼리_결측치를평균값처리'!C570 -> 0 | D570: ='수기_결측치를평균값처리'!D570-'파워쿼리_결측치를평균값처리'!D570 -> 0 | E570: ='수기_결측치를평균값처리'!E570-'파워쿼리_결측치를평균값처리'!E570 -> 0 | F570: ='수기_결측치를평균값처리'!F570-'파워쿼리_결측치를평균값처리'!F570 -> 0 | G570: ='수기_결측치를평균값처리'!G570-'파워쿼리_결측치를평균값처리'!G570 -> 0 | H570: ='수기_결측치를평균값처리'!H570-'파워쿼리_결측치를평균값처리'!H570 -> 0 | I570: ='수기_결측치를평균값처리'!I570-'파워쿼리_결측치를평균값처리'!I570 -> 0 | ... AF570: ='수기_결측치를평균값처리'!AF570-'파워쿼리_결측치를평균값처리'!AF570 -> 0
AG571: =SUM(A1:AF570) -> 0

Sheet 수기_결측치를평균값처리
A1: 구분 | B1: mean radius | C1: mean texture | D1: mean perimeter | E1: mean area | F1: mean smoothness | G1: mean compactness | H1: mean concavity | I1: mean concave points | J1: mean symmetry | K1: mean fractal dimension | L1: radius error | M1: texture error | N1: perimeter error | O1: area error | P1: smoothness error | Q1: compactness error | R1: concavity error | S1: concave points error | T1: symmetry error | U1: fractal dimension error | V1: worst radius | W1: worst texture | X1: worst perimeter | Y1: worst area | Z1: worst smoothness | AA1: worst compactness | AB1: worst concavity | AC1: worst concave points | AD1: worst symmetry | AE1: worst fractal dimension | AF1: target
A2: 0 | B2: 17.99 | C2: 10.38 | D2: 122.8 | E2: 1001 | F2: 0.096298535 | G2: 0.2776 | H2: 0.3001 | I2: 0.1471 | J2: 0.1813125 | K2: 0.07871 | L2: 1.095 | M2: 0.9053 | N2: 8.589 | O2: 153.4 | P2: 0.006399 | Q2: 0.025408436 | R2: 0.05373 | S2: 0.01587 | T2: 0.03003 | U2: 0.006193 | V2: 25.38 | W2: 17.33 | X2: 184.6 | Y2: 882.60879 | Z2: 0.1622 | AA2: 0.6656 | AB2: 0.7119 | AC2: 0.2654 | AD2: 0.4601 | AE2: 0.1189 | AF2: 0
A3: 1 | B3: 20.57 | C3: 19.304297 | D3: 132.9 | E3: 1326 | F3: 0.08474 | G3: 0.07864 | H3: 0.0869 | I3: 0.07017 | J3: 0.1812 | K3: 0.05667 | L3: 0.5435 | M3: 0.7339 | N3: 3.398 | O3: 74.08 | P3: 0.005225 | Q3: 0.025408436 | R3: 0.0186 | S3: 0.0134 | T3: 0.01389 | U3: 0.003532 | V3: 16.288062 | W3: 23.41 | X3: 158.8 | Y3: 1956 | Z3: 0.1238 | AA3: 0.1866 | AB3: 0.2416 | AC3: 0.186 | AD3: 0.275 | AE3: 0.08902 | AF3: 0
A4: 2 | B4: 19.69 | C4: 21.25 | D4: 130 | E4: 1203 | F4: 0.1096 | G4: 0.1599 | H4: 0.1974 | I4: 0.1279 | J4: 0.2069 | K4: 0.05999 | L4: 0.7456 | M4: 0.7869 | N4: 4.585 | O4: 94.03 | P4: 0.00615 | Q4: 0.025408436 | R4: 0.03832 | S4: 0.02058 | T4: 0.0225 | U4: 0.004571 | V4: 23.57 | W4: 25.53 | X4: 152.5 | Y4: 1709 | Z4: 0.1444 | AA4: 0.4245 | AB4: 0.4504 | AC4: 0.243 | AD4: 0.3613 | AE4: 0.08758 | AF4: 0
A5: 3 | B5: 11.42 | C5: 20.38 | D5: 77.58 | E5: 386.1 | F5: 0.1425 | G5: 0.2839 | H5: 0.2414 | I5: 0.1052 | J5: 0.2597 | K5: 0.09744 | L5: 0.4956 | M5: 1.156 | N5: 3.445 | O5: 27.23 | P5: 0.00911 | Q5: 0.025408436 | R5: 0.05661 | S5: 0.01867 | T5: 0.05963 | U5: 0.009208 | V5: 16.288062 | W5: 26.5 | X5: 98.87 | Y5: 567.7 | Z5: 0.2098 | AA5: 0.8663 | AB5: 0.6869 | AC5: 0.2575 | AD5: 0.6638 | AE5: 0.173 | AF5: 0
A6: 4 | B6: 20.29 | C6: 14.34 | D6: 135.1 | E6: 1297 | F6: 0.1003 | G6: 0.10434189 | H6: 0.198 | I6: 0.1043 | J6: 0.1809 | K6: 0.05883 | L6: 0.41285645 | M6: 1.2273826 | N6: 5.438 | O6: 94.44 | P6: 0.01149 | Q6: 0.02461 | R6: 0.032282958 | S6: 0.01885 | T6: 0.01756 | U6: 0.005115 | V6: 22.54 | W6: 16.67 | X6: 152.2 | Y6: 1575 | Z6: 0.1374 | AA6: 0.205 | AB6: 0.4 | AC6: 0.1625 | AD6: 0.28940938 | AE6: 0.083772832 | AF6: 0
A7: 5 | B7: 12.45 | C7: 15.7 | D7: 82.57 | E7: 662.58574 | F7: 0.096298535 | G7: 0.17 | H7: 0.1578 | I7: 0.08089 | J7: 0.2087 | K7: 0.07613 | L7: 0.3345 | M7: 0.8902 | N7: 2.8757826 | O7: 40.834199 | P7: 0.00751 | Q7: 0.03345 | R7: 0.03672 | S7: 0.01137 | T7: 0.02165 | U7: 0.0037882701 | V7: 15.47 | W7: 23.75 | X7: 103.4 | Y7: 741.6 | Z7: 0.1791 | AA7: 0.5249 | AB7: 0.5355 | AC7: 0.1741 | AD7: 0.3985 | AE7: 0.1244 | AF7: 0
A8: 6 | B8: 14.172223 | C8: 19.98 | D8: 119.6 | E8: 1040 | F8: 0.09463 | G8: 0.10434189 | H8: 0.1127 | I8: 0.074 | J8: 0.1794 | K8: 0.05742 | L8: 0.4467 | M8: 0.7732 | N8: 3.18 | O8: 53.91 | P8: 0.004314 | Q8: 0.01382 | R8: 0.02254 | S8: 0.01039 | T8: 0.01369 | U8: 0.002179 | V8: 22.88 | W8: 27.66 | X8: 153.2 | Y8: 1606 | Z8: 0.1442 | AA8: 0.2576 | AB8: 0.3784 | AC8: 0.1932 | AD8: 0.28940938 | AE8: 0.08368 | AF8: 0
A9: 7 | B9: 13.71 | C9: 20.83 | D9: 90.2 | E9: 577.9 | F9: 0.1189 | G9: 0.1645 | H9: 0.09366 | I9: 0.05985 | J9: 0.2196 | K9: 0.07451 | L9: 0.5835 | M9: 1.377 | N9: 3.856 | O9: 50.96 | P9: 0.008805 | Q9: 0.03029 | R9: 0.02488 | S9: 0.01448 | T9: 0.01486 | U9: 0.005412 | V9: 17.06 | W9: 28.14 | X9: 106.755 | Y9: 897 | Z9: 0.1654 | AA9: 0.3682 | AB9: 0.27083677 | AC9: 0.1556 | AD9: 0.3196 | AE9: 0.1151 | AF9: 0.6328125
A10: 8 | B10: 13 | C10: 21.82 | D10: 87.5 | E10: 519.8 | F10: 0.1273 | G10: 0.1932 | H10: 0.089762684 | I10: 0.09353 | J10: 0.235 | K10: 0.07389 | L10: 0.3063 | M10: 1.002 | N10: 2.406 | O10: 24.32 | P10: 0.005731 | Q10: 0.03502 | R10: 0.03553 | S10: 0.01226 | T10: 0.02143 | U10: 0.003749 | V10: 15.49 | W10: 30.73 | X10: 106.755 | Y10: 739.3 | Z10: 0.1703 | AA10: 0.5401 | AB10: 0.539 | AC10: 0.206 | AD10: 0.4378 | AE10: 0.1072 | AF10: 0.6328125
A11: 9 | B11: 12.46 | C11: 24.04 | D11: 83.97 | E11: 475.9 | F11: 0.1186 | G11: 0.2396 | H11: 0.2273 | I11: 0.08543 | J11: 0.203 | K11: 0.08243 | L11: 0.2976 | M11: 1.599 | N11: 2.039 | O11: 23.94 | P11: 0.0070783379 | Q11: 0.07217 | R11: 0.07743 | S11: 0.01432 | T11: 0.01789 | U11: 0.01008 | V11: 15.09 | W11: 40.68 | X11: 97.65 | Y11: 711.4 | Z11: 0.13254033 | AA11: 1.058 | AB11: 1.105 | AC11: 0.221 | AD11: 0.4366 | AE11: 0.083772832 | AF11: 0
A12: 10 | B12: 14.172223 | C12: 23.24 | D12: 102.7 | E12: 797.8 | F12: 0.08206 | G12: 0.06669 | H12: 0.03299 | I12: 0.03323 | J12: 0.1528 | K12: 0.05697 | L12: 0.3795 | M12: 1.2273826 | N12: 2.466 | O12: 40.51 | P12: 0.004029 | Q12: 0.009269 | R12: 0.01101 | S12: 0.007591 | T12: 0.0146 | U12: 0.003042 | V12: 19.19 | W12: 25.619805 | X12: 123.8 | Y12: 1150 | Z12: 0.1181 | AA12: 0.1551 | AB12: 0.1459 | AC12: 0.09975 | AD12: 0.28940938 | AE12: 0.08452 | AF12: 0
A13: 11 | B13: 15.78 | C13: 17.89 | D13: 103.6 | E13: 781 | F13: 0.0971 | G13: 0.1292 | H13: 0.09954 | I13: 0.06606 | J13: 0.1842 | K13: 0.06082 | L13: 0.5058 | M13: 0.9849 | N13: 3.564 | O13: 40.834199 | P13: 0.005771 | Q13: 0.04061 | R13: 0.02791 | S13: 0.011848459 | T13: 0.02008 | U13: 0.004144 | V13: 20.42 | W13: 27.28 | X13: 136.5 | Y13: 1299 | Z13: 0.13254033 | AA13: 0.5609 | AB13: 0.3965 | AC13: 0.181 | AD13: 0.3792 | AE13: 0.1048 | AF13: 0
... A570: 568 | B570: 7.76 | C570: 24.54 | D570: 47.92 | E570: 181 | F570: 0.05263 | G570: 0.04362 | H570: 0 | I570: 0 | J570: 0.1587 | K570: 0.05884 | L570: 0.3857 | M570: 1.428 | N570: 2.548 | O570: 19.15 | P570: 0.007189 | Q570: 0.025408436 | R570: 0 | S570: 0 | T570: 0.02676 | U570: 0.0037882701 | V570: 9.456 | W570: 30.37 | X570: 59.16 | Y570: 268.6 | Z570: 0.13254033 | AA570: 0.06444 | AB570: 0 | AC570: 0 | AD570: 0.2871 | AE570: 0.07039 | AF570: 1

Sheet 파워쿼리_결측치를평균값처리
A1: 구분 | B1: mean radius | C1: mean texture | D1: mean perimeter | E1: mean area | F1: mean smoothness | G1: mean compactness | H1: mean concavity | I1: mean concave points | J1: mean symmetry | K1: mean fractal dimension | L1: radius error | M1: texture error | N1: perimeter error | O1: area error | P1: smoothness error | Q1: compactness error | R1: concavity error | S1: concave points error | T1: symmetry error | U1: fractal dimension error | V1: worst radius | W1: worst texture | X1: worst perimeter | Y1: worst area | Z1: worst smoothness | AA1: worst compactness | AB1: worst concavity | AC1: worst concave points | AD1: worst symmetry | AE1: worst fractal dimension | AF1: target
A2: 0 | B2: 17.99 | C2: 10.38 | D2: 122.8 | E2: 1001 | F2: 0.096298535 | G2: 0.2776 | H2: 0.3001 | I2: 0.1471 | J2: 0.1813125 | K2: 0.07871 | L2: 1.095 | M2: 0.9053 | N2: 8.589 | O2: 153.4 | P2: 0.006399 | Q2: 0.025408436 | R2: 0.05373 | S2: 0.01587 | T2: 0.03003 | U2: 0.006193 | V2: 25.38 | W2: 17.33 | X2: 184.6 | Y2: 882.60879 | Z2: 0.1622 | AA2: 0.6656 | AB2: 0.7119 | AC2: 0.2654 | AD2: 0.4601 | AE2: 0.1189 | AF2: 0
A3: 1 | B3: 20.57 | C3: 19.304297 | D3: 132.9 | E3: 1326 | F3: 0.08474 | G3: 0.07864 | H3: 0.0869 | I3: 0.07017 | J3: 0.1812 | K3: 0.05667 | L3: 0.5435 | M3: 0.7339 | N3: 3.398 | O3: 74.08 | P3: 0.005225 | Q3: 0.025408436 | R3: 0.0186 | S3: 0.0134 | T3: 0.01389 | U3: 0.003532 | V3: 16.288062 | W3: 23.41 | X3: 158.8 | Y3: 1956 | Z3: 0.1238 | AA3: 0.1866 | AB3: 0.2416 | AC3: 0.186 | AD3: 0.275 | AE3: 0.08902 | AF3: 0
A4: 2 | B4: 19.69 | C4: 21.25 | D4: 130 | E4: 1203 | F4: 0.1096 | G4: 0.1599 | H4: 0.1974 | I4: 0.1279 | J4: 0.2069 | K4: 0.05999 | L4: 0.7456 | M4: 0.7869 | N4: 4.585 | O4: 94.03 | P4: 0.00615 | Q4: 0.025408436 | R4: 0.03832 | S4: 0.02058 | T4: 0.0225 | U4: 0.004571 | V4: 23.57 | W4: 25.53 | X4: 152.5 | Y4: 1709 | Z4: 0.1444 | AA4: 0.4245 | AB4: 0.4504 | AC4: 0.243 | AD4: 0.3613 | AE4: 0.08758 | AF4: 0
A5: 3 | B5: 11.42 | C5: 20.38 | D5: 77.58 | E5: 386.1 | F5: 0.1425 | G5: 0.2839 | H5: 0.2414 | I5: 0.1052 | J5: 0.2597 | K5: 0.09744 | L5: 0.4956 | M5: 1.156 | N5: 3.445 | O5: 27.23 | P5: 0.00911 | Q5: 0.025408436 | R5: 0.05661 | S5: 0.01867 | T5: 0.05963 | U5: 0.009208 | V5: 16.288062 | W5: 26.5 | X5: 98.87 | Y5: 567.7 | Z5: 0.2098 | AA5: 0.8663 | AB5: 0.6869 | AC5: 0.2575 | AD5: 0.6638 | AE5: 0.173 | AF5: 0
A6: 4 | B6: 20.29 | C6: 14.34 | D6: 135.1 | E6: 1297 | F6: 0.1003 | G6: 0.10434189 | H6: 0.198 | I6: 0.1043 | J6: 0.1809 | K6: 0.05883 | L6: 0.41285645 | M6: 1.2273826 | N6: 5.438 | O6: 94.44 | P6: 0.01149 | Q6: 0.02461 | R6: 0.032282958 | S6: 0.01885 | T6: 0.01756 | U6: 0.005115 | V6: 22.54 | W6: 16.67 | X6: 152.2 | Y6: 1575 | Z6: 0.1374 | AA6: 0.205 | AB6: 0.4 | AC6: 0.1625 | AD6: 0.28940938 | AE6: 0.083772832 | AF6: 0
A7: 5 | B7: 12.45 | C7: 15.7 | D7: 82.57 | E7: 662.58574 | F7: 0.096298535 | G7: 0.17 | H7: 0.1578 | I7: 0.08089 | J7: 0.2087 | K7: 0.07613 | L7: 0.3345 | M7: 0.8902 | N7: 2.8757826 | O7: 40.834199 | P7: 0.00751 | Q7: 0.03345 | R7: 0.03672 | S7: 0.01137 | T7: 0.02165 | U7: 0.0037882701 | V7: 15.47 | W7: 23.75 | X7: 103.4 | Y7: 741.6 | Z7: 0.1791 | AA7: 0.5249 | AB7: 0.5355 | AC7: 0.1741 | AD7: 0.3985 | AE7: 0.1244 | AF7: 0
A8: 6 | B8: 14.172223 | C8: 19.98 | D8: 119.6 | E8: 1040 | F8: 0.09463 | G8: 0.10434189 | H8: 0.1127 | I8: 0.074 | J8: 0.1794 | K8: 0.05742 | L8: 0.4467 | M8: 0.7732 | N8: 3.18 | O8: 53.91 | P8: 0.004314 | Q8: 0.01382 | R8: 0.02254 | S8: 0.01039 | T8: 0.01369 | U8: 0.002179 | V8: 22.88 | W8: 27.66 | X8: 153.2 | Y8: 1606 | Z8: 0.1442 | AA8: 0.2576 | AB8: 0.3784 | AC8: 0.1932 | AD8: 0.28940938 | AE8: 0.08368 | AF8: 0
A9: 7 | B9: 13.71 | C9: 20.83 | D9: 90.2 | E9: 577.9 | F9: 0.1189 | G9: 0.1645 | H9: 0.09366 | I9: 0.05985 | J9: 0.2196 | K9: 0.07451 | L9: 0.5835 | M9: 1.377 | N9: 3.856 | O9: 50.96 | P9: 0.008805 | Q9: 0.03029 | R9: 0.02488 | S9: 0.01448 | T9: 0.01486 | U9: 0.005412 | V9: 17.06 | W9: 28.14 | X9: 106.755 | Y9: 897 | Z9: 0.1654 | AA9: 0.3682 | AB9: 0.27083677 | AC9: 0.1556 | AD9: 0.3196 | AE9: 0.1151 | AF9: 0.6328125
A10: 8 | B10: 13 | C10: 21.82 | D10: 87.5 | E10: 519.8 | F10: 0.1273 | G10: 0.1932 | H10: 0.089762684 | I10: 0.09353 | J10: 0.235 | K10: 0.07389 | L10: 0.3063 | M10: 1.002 | N10: 2.406 | O10: 24.32 | P10: 0.005731 | Q10: 0.03502 | R10: 0.03553 | S10: 0.01226 | T10: 0.02143 | U10: 0.003749 | V10: 15.49 | W10: 30.73 | X10: 106.755 | Y10: 739.3 | Z10: 0.1703 | AA10: 0.5401 | AB10: 0.539 | AC10: 0.206 | AD10: 0.4378 | AE10: 0.1072 | AF10: 0.6328125
A11: 9 | B11: 12.46 | C11: 24.04 | D11: 83.97 | E11: 475.9 | F11: 0.1186 | G11: 0.2396 | H11: 0.2273 | I11: 0.08543 | J11: 0.203 | K11: 0.08243 | L11: 0.2976 | M11: 1.599 | N11: 2.039 | O11: 23.94 | P11: 0.0070783379 | Q11: 0.07217 | R11: 0.07743 | S11: 0.01432 | T11: 0.01789 | U11: 0.01008 | V11: 15.09 | W11: 40.68 | X11: 97.65 | Y11: 711.4 | Z11: 0.13254033 | AA11: 1.058 | AB11: 1.105 | AC11: 0.221 | AD11: 0.4366 | AE11: 0.083772832 | AF11: 0
A12: 10 | B12: 14.172223 | C12: 23.24 | D12: 102.7 | E12: 797.8 | F12: 0.08206 | G12: 0.06669 | H12: 0.03299 | I12: 0.03323 | J12: 0.1528 | K12: 0.05697 | L12: 0.3795 | M12: 1.2273826 | N12: 2.466 | O12: 40.51 | P12: 0.004029 | Q12: 0.009269 | R12: 0.01101 | S12: 0.007591 | T12: 0.0146 | U12: 0.003042 | V12: 19.19 | W12: 25.619805 | X12: 123.8 | Y12: 1150 | Z12: 0.1181 | AA12: 0.1551 | AB12: 0.1459 | AC12: 0.09975 | AD12: 0.28940938 | AE12: 0.08452 | AF12: 0
A13: 11 | B13: 15.78 | C13: 17.89 | D13: 103.6 | E13: 781 | F13: 0.0971 | G13: 0.1292 | H13: 0.09954 | I13: 0.06606 | J13: 0.1842 | K13: 0.06082 | L13: 0.5058 | M13: 0.9849 | N13: 3.564 | O13: 40.834199 | P13: 0.005771 | Q13: 0.04061 | R13: 0.02791 | S13: 0.011848459 | T13: 0.02008 | U13: 0.004144 | V13: 20.42 | W13: 27.28 | X13: 136.5 | Y13: 1299 | Z13: 0.13254033 | AA13: 0.5609 | AB13: 0.3965 | AC13: 0.181 | AD13: 0.3792 | AE13: 0.1048 | AF13: 0
... A570: 568 | B570: 7.76 | C570: 24.54 | D570: 47.92 | E570: 181 | F570: 0.05263 | G570: 0.04362 | H570: 0 | I570: 0 | J570: 0.1587 | K570: 0.05884 | L570: 0.3857 | M570: 1.428 | N570: 2.548 | O570: 19.15 | P570: 0.007189 | Q570: 0.025408436 | R570: 0 | S570: 0 | T570: 0.02676 | U570: 0.0037882701 | V570: 9.456 | W570: 30.37 | X570: 59.16 | Y570: 268.6 | Z570: 0.13254033 | AA570: 0.06444 | AB570: 0 | AC570: 0 | AD570: 0.2871 | AE570: 0.07039 | AF570: 1

Sheet Sheet1
A1: 구분 | B1: mean radius | C1: mean texture | D1: mean perimeter | E1: mean area | F1: mean smoothness | G1: mean compactness | H1: mean concavity | I1: mean concave points | J1: mean symmetry | K1: mean fractal dimension | L1: radius error | M1: texture error | N1: perimeter error | O1: area error | P1: smoothness error | Q1: compactness error | R1: concavity error | S1: concave points error | T1: symmetry error | U1: fractal dimension error | V1: worst radius | W1: worst texture | X1: worst perimeter | Y1: worst area | Z1: worst smoothness | AA1: worst compactness | AB1: worst concavity | AC1: worst concave points | AD1: worst symmetry | AE1: worst fractal dimension | AF1: target
A2: 0 | B2: 17.99 | C2: 10.38 | D2: 122.8 | E2: 1001 | G2: 0.2776 | H2: 0.3001 | I2: 0.1471 | K2: 0.07871 | L2: 1.095 | M2: 0.9053 | N2: 8.589 | O2: 153.4 | P2: 0.006399 | R2: 0.05373 | S2: 0.01587 | T2: 0.03003 | U2: 0.006193 | V2: 25.38 | W2: 17.33 | X2: 184.6 | Z2: 0.1622 | AA2: 0.6656 | AB2: 0.7119 | AC2: 0.2654 | AD2: 0.4601 | AE2: 0.1189 | AF2: 0
A3: 1 | B3: 20.57 | D3: 132.9 | E3: 1326 | F3: 0.08474 | G3: 0.07864 | H3: 0.0869 | I3: 0.07017 | J3: 0.1812 | K3: 0.05667 | L3: 0.5435 | M3: 0.7339 | N3: 3.398 | O3: 74.08 | P3: 0.005225 | R3: 0.0186 | S3: 0.0134 | T3: 0.01389 | U3: 0.003532 | W3: 23.41 | X3: 158.8 | Y3: 1956 | Z3: 0.1238 | AA3: 0.1866 | AB3: 0.2416 | AC3: 0.186 | AD3: 0.275 | AE3: 0.08902 | AF3: 0
A4: 2 | B4: 19.69 | C4: 21.25 | D4: 130 | E4: 1203 | F4: 0.1096 | G4: 0.1599 | H4: 0.1974 | I4: 0.1279 | J4: 0.2069 | K4: 0.05999 | L4: 0.7456 | M4: 0.7869 | N4: 4.585 | O4: 94.03 | P4: 0.00615 | R4: 0.03832 | S4: 0.02058 | T4: 0.0225 | U4: 0.004571 | V4: 23.57 | W4: 25.53 | X4: 152.5 | Y4: 1709 | Z4: 0.1444 | AA4: 0.4245 | AB4: 0.4504 | AC4: 0.243 | AD4: 0.3613 | AE4: 0.08758 | AF4: 0
A5: 3 | B5: 11.42 | C5: 20.38 | D5: 77.58 | E5: 386.1 | F5: 0.1425 | G5: 0.2839 | H5: 0.2414 | I5: 0.1052 | J5: 0.2597 | K5: 0.09744 | L5: 0.4956 | M5: 1.156 | N5: 3.445 | O5: 27.23 | P5: 0.00911 | R5: 0.05661 | S5: 0.01867 | T5: 0.05963 | U5: 0.009208 | W5: 26.5 | X5: 98.87 | Y5: 567.7 | Z5: 0.2098 | AA5: 0.8663 | AB5: 0.6869 | AC5: 0.2575 | AD5: 0.6638 | AE5: 0.173 | AF5: 0
A6: 4 | B6: 20.29 | C6: 14.34 | D6: 135.1 | E6: 1297 | F6: 0.1003 | H6: 0.198 | I6: 0.1043 | J6: 0.1809 | K6: 0.05883 | N6: 5.438 | O6: 94.44 | P6: 0.01149 | Q6: 0.02461 | S6: 0.01885 | T6: 0.01756 | U6: 0.005115 | V6: 22.54 | W6: 16.67 | X6: 152.2 | Y6: 1575 | Z6: 0.1374 | AA6: 0.205 | AB6: 0.4 | AC6: 0.1625 | AF6: 0
A7: 5 | B7: 12.45 | C7: 15.7 | D7: 82.57 | G7: 0.17 | H7: 0.1578 | I7: 0.08089 | J7: 0.2087 | K7: 0.07613 | L7: 0.3345 | M7: 0.8902 | P7: 0.00751 | Q7: 0.03345 | R7: 0.03672 | S7: 0.01137 | T7: 0.02165 | V7: 15.47 | W7: 23.75 | X7: 103.4 | Y7: 741.6 | Z7: 0.1791 | AA7: 0.5249 | AB7: 0.5355 | AC7: 0.1741 | AD7: 0.3985 | AE7: 0.1244 | AF7: 0
A8: 6 | C8: 19.98 | D8: 119.6 | E8: 1040 | F8: 0.09463 | H8: 0.1127 | I8: 0.074 | J8: 0.1794 | K8: 0.05742 | L8: 0.4467 | M8: 0.7732 | N8: 3.18 | O8: 53.91 | P8: 0.004314 | Q8: 0.01382 | R8: 0.02254 | S8: 0.01039 | T8: 0.01369 | U8: 0.002179 | V8: 22.88 | W8: 27.66 | X8: 153.2 | Y8: 1606 | Z8: 0.1442 | AA8: 0.2576 | AB8: 0.3784 | AC8: 0.1932 | AE8: 0.08368 | AF8: 0
A9: 7 | B9: 13.71 | C9: 20.83 | D9: 90.2 | E9: 577.9 | F9: 0.1189 | G9: 0.1645 | H9: 0.09366 | I9: 0.05985 | J9: 0.2196 | K9: 0.07451 | L9: 0.5835 | M9: 1.377 | N9: 3.856 | O9: 50.96 | P9: 0.008805 | Q9: 0.03029 | R9: 0.02488 | S9: 0.01448 | T9: 0.01486 | U9: 0.005412 | V9: 17.06 | W9: 28.14 | Y9: 897 | Z9: 0.1654 | AA9: 0.3682 | AC9: 0.1556 | AD9: 0.3196 | AE9: 0.1151
A10: 8 | B10: 13 | C10: 21.82 | D10: 87.5 | E10: 519.8 | F10: 0.1273 | G10: 0.1932 | I10: 0.09353 | J10: 0.235 | K10: 0.07389 | L10: 0.3063 | M10: 1.002 | N10: 2.406 | O10: 24.32 | P10: 0.005731 | Q10: 0.03502 | R10: 0.03553 | S10: 0.01226 | T10: 0.02143 | U10: 0.003749 | V10: 15.49 | W10: 30.73 | Y10: 739.3 | Z10: 0.1703 | AA10: 0.5401 | AB10: 0.539 | AC10: 0.206 | AD10: 0.4378 | AE10: 0.1072
A11: 9 | B11: 12.46 | C11: 24.04 | D11: 83.97 | E11: 475.9 | F11: 0.1186 | G11: 0.2396 | H11: 0.2273 | I11: 0.08543 | J11: 0.203 | K11: 0.08243 | L11: 0.2976 | M11: 1.599 | N11: 2.039 | O11: 23.94 | Q11: 0.07217 | R11: 0.07743 | S11: 0.01432 | T11: 0.01789 | U11: 0.01008 | V11: 15.09 | W11: 40.68 | X11: 97.65 | Y11: 711.4 | AA11: 1.058 | AB11: 1.105 | AC11: 0.221 | AD11: 0.4366 | AF11: 0
A12: 10 | C12: 23.24 | D12: 102.7 | E12: 797.8 | F12: 0.08206 | G12: 0.06669 | H12: 0.03299 | I12: 0.03323 | J12: 0.1528 | K12: 0.05697 | L12: 0.3795 | N12: 2.466 | O12: 40.51 | P12: 0.004029 | Q12: 0.009269 | R12: 0.01101 | S12: 0.007591 | T12: 0.0146 | U12: 0.003042 | V12: 19.19 | X12: 123.8 | Y12: 1150 | Z12: 0.1181 | AA12: 0.1551 | AB12: 0.1459 | AC12: 0.09975 | AE12: 0.08452 | AF12: 0
A13: 11 | B13: 15.78 | C13: 17.89 | D13: 103.6 | E13: 781 | F13: 0.0971 | G13: 0.1292 | H13: 0.09954 | I13: 0.06606 | J13: 0.1842 | K13: 0.06082 | L13: 0.5058 | M13: 0.9849 | N13: 3.564 | P13: 0.005771 | Q13: 0.04061 | R13: 0.02791 | T13: 0.02008 | U13: 0.004144 | V13: 20.42 | W13: 27.28 | X13: 136.5 | Y13: 1299 | AA13: 0.5609 | AB13: 0.3965 | AC13: 0.181 | AD13: 0.3792 | AE13: 0.1048 | AF13: 0
A14: 12 | B14: 19.17 | C14: 24.8 | D14: 132.4 | E14: 1123 | F14: 0.0974 | H14: 0.2065 | I14: 0.1118 | J14: 0.2397 | K14: 0.078 | L14: 0.9555 | M14: 3.568 | N14: 11.07 | O14: 116.2 | P14: 0.003139 | R14: 0.0889 | S14: 0.0409 | T14: 0.04484 | U14: 0.01284 | V14: 20.96 | W14: 29.94 | X14: 151.7 | Y14: 1332 | Z14: 0.1037 | AA14: 0.3903 | AB14: 0.3639 | AC14: 0.1767 | AD14: 0.3176 | AE14: 0.1023 | AF14: 0
A15: 13 | B15: 15.85 | C15: 23.95 | D15: 103.7 | E15: 782.7 | F15: 0.08401 | G15: 0.1002 | H15: 0.09938 | I15: 0.05364 | J15: 0.1847 | K15: 0.05338 | M15: 1.078 | N15: 2.903 | O15: 36.58 | Q15: 0.03126 | R15: 0.05051 | S15: 0.01992 | T15: 0.02981 | V15: 16.84 | W15: 27.66 | X15: 112 | Y15: 876.5 | Z15: 0.1131 | AA15: 0.1924 | AB15: 0.2322 | AC15: 0.1119 | AD15: 0.2809 | AE15: 0.06287 | AF15: 0
A16: 14 | B16: 13.73 | C16: 22.61 | D16: 93.6 | E16: 578.3 | F16: 0.1131 | G16: 0.2293 | H16: 0.2128 | I16: 0.08025 | J16: 0.2069 | K16: 0.07682 | L16: 0.2121 | M16: 1.169 | N16: 2.061 | O16: 19.21 | P16: 0.006429 | Q16: 0.05936 | R16: 0.05501 | S16: 0.01628 | U16: 0.008093 | V16: 15.03 | W16: 32.01 | X16: 108.8 | Y16: 697.7 | Z16: 0.1651 | AA16: 0.7725 | AB16: 0.6943 | AC16: 0.2208 | AD16: 0.3596 | AE16: 0.1431 | AF16: 0
A17: 15 | B17: 14.54 | D17: 96.73 | E17: 658.8 | F17: 0.1139 | G17: 0.1595 | H17: 0.1639 | I17: 0.07364 | J17: 0.2303 | K17: 0.07077 | L17: 0.37 | M17: 1.033 | N17: 2.879 | O17: 32.55 | P17: 0.005607 | Q17: 0.0424 | R17: 0.04741 | S17: 0.0109 | T17: 0.01857 | U17: 0.005466 | V17: 17.46 | W17: 37.13 | X17: 124.1 | Y17: 943.2 | Z17: 0.1678 | AA17: 0.6577 | AB17: 0.7026 | AC17: 0.1712 | AD17: 0.4218 | AE17: 0.1341 | AF17: 0
A18: 16 | B18: 14.68 | C18: 20.13 | D18: 94.74 | F18: 0.09867 | G18: 0.072 | H18: 0.07395 | I18: 0.05259 | J18: 0.1586 | K18: 0.05922 | L18: 0.4727 | M18: 1.24 | N18: 3.195 | O18: 45.4 | P18: 0.005718 | Q18: 0.01162 | R18: 0.01998 | S18: 0.01109 | T18: 0.0141 | U18: 0.002085 | V18: 19.07 | W18: 30.88 | X18: 123.4 | Y18: 1138 | Z18: 0.1464 | AB18: 0.2914 | AC18: 0.1609 | AD18: 0.3029 | AE18: 0.08216 | AF18: 0
A19: 17 | B19: 16.13 | C19: 20.68 | D19: 108.1 | E19: 798.8 | F19: 0.117 | G19: 0.2022 | H19: 0.1722 | I19: 0.1028 | J19: 0.2164 | K19: 0.07356 | L19: 0.5692 | M19: 1.073 | N19: 3.854 | O19: 54.18 | P19: 0.007026 | Q19: 0.02501 | S19: 0.01297 | T19: 0.01689 | U19: 0.004142 | V19: 20.96 | W19: 31.48 | X19: 136.8 | Y19: 1315 | Z19: 0.1789 | AA19: 0.4233 | AB19: 0.4784 | AC19: 0.2073 | AD19: 0.3706 | AE19: 0.1142 | AF19: 0
A20: 18 | B20: 19.81 | C20: 22.15 | D20: 130 | E20: 1260 | F20: 0.09831 | G20: 0.1027 | H20: 0.1479 | I20: 0.09498 | J20: 0.1582 | K20: 0.05395 | L20: 0.7582 | M20: 1.017 | N20: 5.865 | O20: 112.4 | P20: 0.006494 | Q20: 0.01893 | R20: 0.03391 | S20: 0.01521 | T20: 0.01356 | U20: 0.001997 | V20: 27.32 | W20: 30.88 | X20: 186.8 | Y20: 2398 | Z20: 0.1512 | AA20: 0.315 | AB20: 0.5372 | AC20: 0.2388 | AD20: 0.2768 | AE20: 0.07615 | AF20: 0
A21: 19 | B21: 13.54 | C21: 14.36 | D21: 87.46 | E21: 566.3 | F21: 0.09779 | G21: 0.08129 | H21: 0.06664 | I21: 0.04781 | J21: 0.1885 | K21: 0.05766 | L21: 0.2699 | M21: 0.7886 | N21: 2.058 | O21: 23.56 | P21: 0.008462 | Q21: 0.0146 | R21: 0.02387 | S21: 0.01315 | T21: 0.0198 | U21: 0.0023 | V21: 15.11 | W21: 19.26 | X21: 99.7 | Y21: 711.2 | Z21: 0.144 | AA21: 0.1773 | AB21: 0.239 | AC21: 0.1288 | AD21: 0.2977 | AE21: 0.07259 | AF21: 1
A22: 20 | B22: 13.08 | C22: 15.71 | E22: 520 | F22: 0.1075 | G22: 0.127 | H22: 0.04568 | I22: 0.0311 | K22: 0.06811 | M22: 0.7477 | O22: 14.67 | P22: 0.004097 | Q22: 0.01898 | R22: 0.01698 | S22: 0.00649 | T22: 0.01678 | U22: 0.002425 | W22: 20.49 | X22: 96.09 | Y22: 630.5 | Z22: 0.1312 | AA22: 0.2776 | AB22: 0.189 | AC22: 0.07283 | AD22: 0.3184 | AE22: 0.08183 | AF22: 1
A23: 21 | B23: 9.504 | C23: 12.44 | E23: 273.9 | F23: 0.1024 | G23: 0.06492 | H23: 0.02956 | I23: 0.02076 | J23: 0.1815 | K23: 0.06905 | L23: 0.2773 | M23: 0.9768 | N23: 1.909 | O23: 15.7 | P23: 0.009606 | Q23: 0.01432 | R23: 0.01985 | S23: 0.01421 | T23: 0.02027 | U23: 0.002968 | V23: 10.23 | W23: 15.66 | X23: 65.13 | Y23: 314.9 | Z23: 0.1324 | AB23: 0.08867 | AC23: 0.06227 | AD23: 0.245 | AE23: 0.07773 | AF23: 1
A24: 22 | B24: 15.34 | C24: 14.26 | E24: 704.4 | F24: 0.1073 | G24: 0.2135 | H24: 0.2077 | I24: 0.09756 | K24: 0.07032 | L24: 0.4388 | M24: 0.7096 | N24: 3.384 | O24: 44.91 | Q24: 0.05328 | R24: 0.06446 | S24: 0.02252 | T24: 0.03672 | U24: 0.004394 | W24: 19.08 | X24: 125.1 | Y24: 980.9 | AA24: 0.5954 | AB24: 0.6305 | AC24: 0.2393 | AD24: 0.4667 | AE24: 0.09946 | AF24: 0
A25: 23 | B25: 21.16 | C25: 23.04 | E25: 1404 | F25: 0.09428 | G25: 0.1022 | H25: 0.1097 | I25: 0.08632 | L25: 0.6917 | M25: 1.127 | N25: 4.303 | O25: 93.99 | P25: 0.004728 | Q25: 0.01259 | R25: 0.01715 | S25: 0.01038 | T25: 0.01083 | U25: 0.001987 | V25: 29.17 | W25: 35.59 | X25: 188 | Y25: 2615 | Z25: 0.1401 | AA25: 0.26 | AB25: 0.3155 | AC25: 0.2009 | AD25: 0.2822 | AE25: 0.07526 | AF25: 0
A26: 24 | B26: 16.65 | C26: 21.38 | D26: 110 | E26: 904.6 | F26: 0.1121 | G26: 0.1457 | H26: 0.1525 | I26: 0.0917 | J26: 0.1995 | K26: 0.0633 | L26: 0.8068 | M26: 0.9017 | N26: 5.455 | O26: 102.6 | P26: 0.006048 | Q26: 0.01882 | R26: 0.02741 | S26: 0.0113 | T26: 0.01468 | U26: 0.002801 | V26: 26.46 | W26: 31.56 | X26: 177 | Y26: 2215 | AA26: 0.3578 | AB26: 0.4695 | AC26: 0.2095 | AD26: 0.3613 | AE26: 0.09564 | AF26: 0
A27: 25 | B27: 17.14 | C27: 16.4 | D27: 116 | E27: 912.7 | F27: 0.1186 | G27: 0.2276 | H27: 0.2229 | J27: 0.304 | K27: 0.07413 | L27: 1.046 | M27: 0.976 | N27: 7.276 | O27: 111.4 | P27: 0.008029 | Q27: 0.03799 | R27: 0.03732 | S27: 0.02397 | U27: 0.007444 | V27: 22.25 | W27: 21.4 | X27: 152.4 | Y27: 1461 | Z27: 0.1545 | AA27: 0.3949 | AB27: 0.3853 | AC27: 0.255 | AD27: 0.4066 | AE27: 0.1059 | AF27: 0
A28: 26 | B28: 14.58 | D28: 97.41 | E28: 644.8 | F28: 0.1054 | G28: 0.1868 | H28: 0.1425 | I28: 0.08783 | J28: 0.2252 | K28: 0.06924 | L28: 0.2545 | M28: 0.9832 | O28: 21.05 | P28: 0.004452 | Q28: 0.03055 | S28: 0.01352 | T28: 0.01454 | U28: 0.003711 | V28: 17.62 | W28: 33.21 | X28: 122.4 | Y28: 896.9 | Z28: 0.1525 | AA28: 0.6643 | AB28: 0.5539 | AC28: 0.2701 | AD28: 0.4264 | AE28: 0.1275 | AF28: 0
A29: 27 | B29: 18.61 | C29: 20.25 | D29: 122.1 | E29: 1094 | F29: 0.0944 | G29: 0.1066 | H29: 0.149 | I29: 0.07731 | J29: 0.1697 | K29: 0.05699 | L29: 0.8529 | M29: 1.849 | N29: 5.632 | O29: 93.54 | P29: 0.01075 | Q29: 0.02722 | R29: 0.05081 | S29: 0.01911 | T29: 0.02293 | V29: 21.31 | W29: 27.26 | X29: 139.9 | Y29: 1403 | Z29: 0.1338 | AA29: 0.2117 | AB29: 0.3446 | AC29: 0.149 | AD29: 0.2341 | AF29: 0
A30: 28 | B30: 15.3 | C30: 25.27 | D30: 102.4 | E30: 732.4 | F30: 0.1082 | G30: 0.1697 | H30: 0.1683 | I30: 0.08751 | J30: 0.1926 | K30: 0.0654 | L30: 0.439 | M30: 1.012 | N30: 3.498 | O30: 43.5 | P30: 0.005233 | R30: 0.03576 | T30: 0.01768 | U30: 0.002967 | V30: 20.27 | W30: 36.71 | X30: 149.3 | Y30: 1269 | Z30: 0.1641 | AA30: 0.611 | AB30: 0.6335 | AC30: 0.2024 | AD30: 0.4027 | AE30: 0.09876 | AF30: 0
A31: 29 | C31: 15.05 | E31: 955.1 | F31: 0.09847 | G31: 0.1157 | H31: 0.09875 | I31: 0.07953 | K31: 0.06149 | L31: 0.6003 | M31: 0.8225 | N31: 4.655 | O31: 61.1 | P31: 0.005627 | Q31: 0.03033 | R31: 0.03407 | S31: 0.01354 | T31: 0.01925 | V31: 20.01 | W31: 19.52 | X31: 134.9 | Y31: 1227 | Z31: 0.1255 | AC31: 0.1456 | AD31: 0.2756 | AE31: 0.07919 | AF31: 0
A32: 30 | C32: 25.11 | E32: 1088 | F32: 0.1064 | H32: 0.2319 | J32: 0.2183 | K32: 0.06197 | L32: 0.8307 | M32: 1.466 | N32: 5.574 | O32: 105 | P32: 0.006248 | Q32: 0.03374 | R32: 0.05196 | S32: 0.01158 | T32: 0.02007 | U32: 0.00456 | V32: 23.15 | W32: 34.01 | X32: 160.5 | Y32: 1670 | Z32: 0.1491 | AB32: 0.6133 | AC32: 0.1848 | AD32: 0.3444 | AF32: 0
A33: 31 | B33: 11.84 | C33: 18.7 | D33: 77.93 | E33: 440.6 | F33: 0.1109 | G33: 0.1516 | H33: 0.1218 | I33: 0.05182 | J33: 0.2301 | K33: 0.07799 | L33: 0.4825 | M33: 1.03 | N33: 3.475 | P33: 0.005551 | R33: 0.04205 | S33: 0.01044 | T33: 0.02273 | U33: 0.005667 | V33: 16.82 | W33: 28.12 | X33: 119.4 | Y33: 888.7 | Z33: 0.1637 | AB33: 0.6956 | AC33: 0.1546 | AD33: 0.4761 | AE33: 0.1402
A34: 32 | B34: 17.02 | C34: 23.98 | D34: 112.8 | E34: 899.3 | F34: 0.1197 | H34: 0.2417 | I34: 0.1203 | L34: 0.6009 | N34: 3.999 | O34: 67.78 | P34: 0.008268 | Q34: 0.03082 | R34: 0.05042 | S34: 0.01112 | T34: 0.02102 | U34: 0.003854 | W34: 32.09 | X34: 136.1 | Y34: 1344 | Z34: 0.1634 | AA34: 0.3559 | AB34: 0.5588 | AC34: 0.1847 | AE34: 0.08482
A35: 33 | B35: 19.27 | C35: 26.47 | D35: 127.9 | E35: 1162 | F35: 0.09401 | G35: 0.1719 | I35: 0.07593 | J35: 0.1853 | K35: 0.06261 | M35: 0.6062 | N35: 3.528 | P35: 0.005015 | Q35: 0.03318 | R35: 0.03497 | S35: 0.009643 | U35: 0.003896 | V35: 24.15 | W35: 30.9 | X35: 161.4 | Y35: 1813 | Z35: 0.1509 | AA35: 0.659 | AB35: 0.6091 | AC35: 0.1785 | AD35: 0.3672 | AE35: 0.1123 | AF35: 0
A36: 34 | B36: 16.13 | C36: 17.88 | D36: 107 | E36: 807.2 | G36: 0.1559 | H36: 0.1354 | I36: 0.07752 | K36: 0.06515 | L36: 0.334 | M36: 0.6857 | N36: 2.183 | O36: 35.03 | P36: 0.004185 | Q36: 0.02868 | R36: 0.02664 | S36: 0.009067 | T36: 0.01703 | U36: 0.003817 | V36: 20.21 | W36: 27.26 | X36: 132.7 | Y36: 1261 | Z36: 0.1446 | AA36: 0.5804 | AB36: 0.5274 | AC36: 0.1864 | AD36: 0.427 | AE36: 0.1233 | AF36: 0
A37: 35 | B37: 16.74 | C37: 21.59 | D37: 110.1 | E37: 869.5 | F37: 0.0961 | G37: 0.1336 | H37: 0.1348 | I37: 0.06018 | J37: 0.1896 | K37: 0.05656 | L37: 0.4615 | M37: 0.9197 | N37: 3.008 | O37: 45.19 | P37: 0.005776 | Q37: 0.02499 | R37: 0.03695 | S37: 0.01195 | U37: 0.002665 | X37: 133.5 | Y37: 1229 | Z37: 0.1563 | AA37: 0.3835 | AB37: 0.5409 | AC37: 0.1813 | AD37: 0.4863 | AE37: 0.08633 | AF37: 0
A38: 36 | B38: 14.25 | C38: 21.72 | D38: 93.63 | E38: 633 | F38: 0.09823 | G38: 0.1098 | H38: 0.1319 | I38: 0.05598 | J38: 0.1885 | K38: 0.06125 | M38: 1.019 | O38: 24.91 | P38: 0.005878 | Q38: 0.02995 | R38: 0.04815 | S38: 0.01161 | T38: 0.02028 | U38: 0.004022 | V38: 15.89 | W38: 30.36 | X38: 116.2 | Y38: 799.6 | Z38: 0.1446 | AA38: 0.4238 | AB38: 0.5186 | AD38: 0.3591 | AE38: 0.1014 | AF38: 0
A39: 37 | B39: 13.03 | C39: 18.42 | D39: 82.61 | E39: 523.8 | F39: 0.08983 | G39: 0.03766 | H39: 0.02562 | I39: 0.02923 | J39: 0.1467 | K39: 0.05863 | L39: 0.1839 | M39: 2.342 | N39: 1.17 | O39: 14.16 | P39: 0.004352 | Q39: 0.004899 | R39: 0.01343 | S39: 0.01164 | T39: 0.02671 | U39: 0.001777 | V39: 13.3 | W39: 22.81 | X39: 84.46 | Y39: 545.9 | Z39: 0.09701 | AA39: 0.04619 | AB39: 0.04833 | AC39: 0.05013 | AD39: 0.1987 | AE39: 0.06169 | AF39: 1
A40: 38 | B40: 14.99 | C40: 25.2 | D40: 95.54 | E40: 698.8 | F40: 0.09387 | G40: 0.05131 | I40: 0.02899 | J40: 0.1565 | L40: 1.214 | M40: 2.188 | N40: 8.077 | O40: 106 | P40: 0.006883 | Q40: 0.01094 | R40: 0.01818 | T40: 0.007882 | U40: 0.001754 | V40: 14.99 | W40: 25.2 | Y40: 698.8 | Z40: 0.09387 | AA40: 0.05131 | AC40: 0.02899 | AD40: 0.1565 | AE40: 0.05504 | AF40: 0
...

Sheet M코드
A1: let 원본 = Excel.CurrentWorkbook(){[Name="표1"]}[Content], 컬럼목록 = Table.ColumnNames(원본), 평균값대체 = (테이블, 컬럼이름) => let 컬럼 = Table.Column(테이블, 컬럼이름), 평균 = List.Average(List.Select(컬럼, each _ <> null)), 대체된테이블 = Table.ReplaceValue(테이블, null, 평균, Replacer.ReplaceValue, {컬럼이름}) in 대체된테이블, 결과 = List.Accumulate(컬럼목록, 원본, (상태, 컬럼) => 평균값대체(상태, 컬럼)) in 결과
A2: https://chatgpt.com/share/e/67322267-e1ec-8009-9e3f-80871be1a5f5
